[0m15:21:16.573949 [debug] [MainThread]: Sending event: {'category': 'dbt', 'action': 'invocation', 'label': 'start', 'context': [<snowplow_tracker.self_describing_json.SelfDescribingJson object at 0x7f5d4b00fd50>, <snowplow_tracker.self_describing_json.SelfDescribingJson object at 0x7f5d4bb549d0>, <snowplow_tracker.self_describing_json.SelfDescribingJson object at 0x7f5d4b023bd0>]}


============================== 15:21:16.578820 | 574e2809-97dd-4376-b244-6800929d41b0 ==============================
[0m15:21:16.578820 [info ] [MainThread]: Running with dbt=1.5.9
[0m15:21:16.580051 [debug] [MainThread]: running dbt with arguments {'printer_width': '80', 'indirect_selection': 'eager', 'log_cache_events': 'False', 'write_json': 'True', 'partial_parse': 'True', 'cache_selected_only': 'False', 'warn_error': 'None', 'debug': 'False', 'profiles_dir': './profiles/', 'log_path': 'logs', 'version_check': 'True', 'fail_fast': 'False', 'use_colors': 'True', 'use_experimental_parser': 'False', 'no_print': 'None', 'quiet': 'False', 'log_format': 'default', 'static_parser': 'True', 'warn_error_options': 'WarnErrorOptions(include=[], exclude=[])', 'introspect': 'True', 'target_path': 'None', 'send_anonymous_usage_stats': 'True'}
[0m15:21:16.580731 [info ] [MainThread]: Creating dbt configuration folder at ./profiles/
[0m15:21:41.276413 [debug] [MainThread]: Starter project path: /home/joshua.garza/dbt/lib64/python3.7/site-packages/dbt/include/starter_project
[0m15:22:11.268008 [error] [MainThread]: Encountered an error:
[Errno 2] No such file or directory: 'profiles/profiles.yml'
[0m15:22:11.270536 [error] [MainThread]: Traceback (most recent call last):
  File "/home/joshua.garza/dbt/lib64/python3.7/site-packages/dbt/cli/requires.py", line 86, in wrapper
    result, success = func(*args, **kwargs)
  File "/home/joshua.garza/dbt/lib64/python3.7/site-packages/dbt/cli/requires.py", line 71, in wrapper
    return func(*args, **kwargs)
  File "/home/joshua.garza/dbt/lib64/python3.7/site-packages/dbt/cli/main.py", line 475, in init
    results = task.run()
  File "/home/joshua.garza/dbt/lib64/python3.7/site-packages/dbt/task/init.py", line 307, in run
    self.create_profile_from_target(adapter, profile_name=project_name)
  File "/home/joshua.garza/dbt/lib64/python3.7/site-packages/dbt/task/init.py", line 180, in create_profile_from_target
    self.create_profile_from_profile_template(profile_template, profile_name)
  File "/home/joshua.garza/dbt/lib64/python3.7/site-packages/dbt/task/init.py", line 167, in create_profile_from_profile_template
    self.write_profile(profile, profile_name)
  File "/home/joshua.garza/dbt/lib64/python3.7/site-packages/dbt/task/init.py", line 157, in write_profile
    with open(profiles_filepath, "w") as f:
FileNotFoundError: [Errno 2] No such file or directory: 'profiles/profiles.yml'

[0m15:22:11.272826 [debug] [MainThread]: Command `dbt init` failed at 15:22:11.272582 after 54.71 seconds
[0m15:22:11.273571 [debug] [MainThread]: Sending event: {'category': 'dbt', 'action': 'invocation', 'label': 'end', 'context': [<snowplow_tracker.self_describing_json.SelfDescribingJson object at 0x7f5d4b034c90>, <snowplow_tracker.self_describing_json.SelfDescribingJson object at 0x7f5d46cdb410>, <snowplow_tracker.self_describing_json.SelfDescribingJson object at 0x7f5d4cb82450>]}
[0m15:22:11.274262 [debug] [MainThread]: Flushing usage events
